Workbook

Sheet Master Requirements Tracker
B2: Nibbl AI — Master Requirements Tracker
B3: Mapped to the Master Document (Nibbl_Master_Requirements_Consistency_Final). Status as of 11 Oct 2026. One row per requirement. Completed = works end to end, tested and can be demonstrated; anything with a missing piece stays In Progress.
C4: TOTAL REQUIREMENTS | D4: COMPLETED | E4: IN PROGRESS | F4: IN REVIEW | G4: PLANNED | H4: COMPLETION RATE
C5: =COUNTA(D9:D158) -> 150 | D5: =COUNTIF(F9:F158,"Completed") -> 130 | E5: =COUNTIF(F9:F158,"In Progress") -> 13 | F5: =COUNTIF(F9:F158,"In Review") -> 2 | G5: =COUNTIF(F9:F158,"Planned") -> 5 | H5: =IF(C5>0,D5/C5,0) -> 0.86666667
C6: Master Document requirements | D6: Works end to end, tested, demoable | E6: Partly built — gap in Notes | F6: Waiting on a third party | G6: Not started yet | H6: Completed ÷ total
B8: # | C8: Master Document Section | D8: Master Requirement | E8: What Was Delivered | F8: Status | G8: Platform | H8: Mobile App | I8: Where to See It | J8: How to Test | K8: Open Items / Notes | L8: Evidence (screenshot / video link) | M8: Checklist Ref
B9: 1 | C9: Brand Dashboard Home | D9: Brand name in header and welcome message | E9: Brand name from Brand Settings. | F9: Completed | G9: Brand Dashboard | H9: — | I9: Dashboard | J9: Log in as a brand; check the welcome line. | M9: #1
B10: 2 | C10: Brand Dashboard Home | D10: Navigation includes Tag Generator and Plans | E10: Both in the sidebar. | F10: Completed | G10: Brand Dashboard | H10: — | I10: Sidebar | J10: Open both pages. | M10: #35, #37
B11: 3 | C11: Brand Dashboard Home | D11: Current plan shown once, linked to Plans | E11: Plan name in the header opens Plans. | F11: Completed | G11: Brand Dashboard | H11: — | I11: Header → Plan | J11: Click the plan name. | M11: #35
B12: 4 | C12: Brand Dashboard Home | D12: Available Funds in header, linked to Wallet | E12: Shows current Available Funds; opens Wallet. | F12: Completed | G12: Brand Dashboard | H12: — | I12: Header | J12: Click Available Funds. | M12: #1
B13: 5 | C13: Brand Dashboard Home | D13: Date range — default Last 30 Days, selectable | E13: Date range selector (7 / 30 / 90 days / 12 months) drives both snapshots and the Campaign Performance table. | F13: Completed | G13: Brand Dashboard + Backend / API | H13: — | I13: Dashboard → Date range | J13: Switch the range; snapshot titles and table results update. | M13: #1
B14: 6 | C14: Brand Dashboard Home | D14: Rebate snapshot: claims, redemptions, redemption rate, Total Brand Cost + cost per redemption | E14: As specified, no mini charts/badges. | F14: Completed | G14: Brand Dashboard | H14: — | I14: Dashboard | J14: Compare with Redemptions for 30 days. | M14: #1, #28
B15: 7 | C15: Brand Dashboard Home | D15: Review snapshot: invitations, completed, completion rate, Total Brand Cost + cost per review | E15: As specified. | F15: Completed | G15: Brand Dashboard | H15: — | I15: Dashboard | J15: Compare with Review Management. | M15: #1, #28
B16: 8 | C16: Brand Dashboard Home | D16: Campaign Performance table (incl. ended; type filter; spend; results) | E16: Rebate + review campaigns; results = claims / redemptions or invitations / completed reviews for the selected range. | F16: Completed | G16: Brand Dashboard + Backend / API | H16: — | I16: Dashboard → Campaign Performance | J16: Filter by type; check review results. | M16: #1
B17: 9 | C17: Product Library | D17: Page controls: product count + Add Product | E17: Count and Add Product button. | F17: Completed | G17: Brand Dashboard | H17: — | I17: Product Library | J17: Open Product Library. | M17: #2
B18: 10 | C18: Product Library | D18: Product cards: image, name/flavor/size, rating, category, Product ID, receipt alias count, Edit | E18: Cards with image, details, rating, Edit. | F18: In Progress | G18: Brand Dashboard | H18: — | I18: Product Library | J18: Compare a card with the Master mockup. | K18: Alias count on the card to confirm against the mockup. | M18: #2
B19: 11 | C19: Product Library | D19: Product identity: separate record per flavor/size with permanent Product ID | E19: Flavor, format, size fields; ID assigned on save. | F19: In Progress | G19: Brand Dashboard + Backend / API | H19: — | I19: Add / Edit Product | J19: Create two sizes of one product. | K19: Separate Unit and Pack Count fields from the mockup aren't built (size is one field). | M19: #2
B20: 12 | C20: Product Library | D20: Product description kept for AI review questions | E20: Description sent to the AI for review questions. | F20: Completed | G20: Brand Dashboard + Backend / API | H20: — | I20: Add / Edit Product | J20: Fill the description. | M20: #2, #24
B21: 13 | C21: Product Library | D21: Standardized, admin-managed categories; brands can request a category | E21: Category is free text today. | F21: Planned | G21: Brand Dashboard + Admin Dashboard | H21: — | I21: — | J21: — | K21: Admin category list + 'Request category' not built. | M21: —
B22: 14 | C22: Product Library | D22: Optional UPC / SKU | E22: SKU field stored. | F22: Completed | G22: Brand Dashboard | H22: — | I22: Add / Edit Product | J22: Enter a SKU and save. | M22: #2
B23: 15 | C23: Product Library | D23: Receipt matching aliases: retailer + receipt text + optional item code | E23: Aliases (receipt text) added on the product or saved in manual review. | F23: In Progress | G23: Brand Dashboard + Backend / API | H23: — | I23: Product → Aliases; Redemptions → review | J23: Add an alias and upload a matching receipt. | K23: Alias retailer and item code fields not built (text only). | M23: #2, #21
B24: 16 | C24: Product Library | D24: Clickable rating opens Review Management filtered to the product | E24: Rating links to filtered Review Management. | F24: Completed | G24: Brand Dashboard | H24: — | I24: Product details → rating | J24: Click a product rating. | M24: #3
B25: 17 | C25: Product Library | D25: Add Product: same single-page fields as Edit; ID assigned on save | E25: Same form for add and edit. | F25: Completed | G25: Brand Dashboard | H25: — | I25: Add Product | J25: Add a product. | M25: #2
B26: 18 | C26: Product Library | D26: Delete Product: type DELETE; history preserved | E26: Confirmation + archive keeps reviews/redemptions. | F26: Completed | G26: Brand Dashboard | H26: — | I26: Edit Product → Delete | J26: Delete with and without typing DELETE. | M26: #3
B27: 19 | C27: Rebate Campaigns List | D27: Status tabs with counts (Draft, Pending Review, Scheduled, Active, Paused, Changes Requested, Ended) | E27: Status tabs on the rebate list. | F27: Completed | G27: Brand Dashboard | H27: — | I27: Rebate Campaigns | J27: Switch tabs. | M27: #7
B28: 20 | C28: Rebate Campaigns List | D28: 'X of Y active campaigns used — Upgrade' banner | E28: Usage bar with plan name and Upgrade button to Plans. | F28: Completed | G28: Brand Dashboard | H28: — | I28: Rebate Campaigns | J28: Activate campaigns up to the limit; click Upgrade. | M28: #34
B29: 21 | C29: Rebate Campaigns List | D29: Campaign cards: image, claims, active claims, pending review, redemptions, rate, total spend, current cycle claims | E29: Cards with metrics and 'X of Y' current cycle. | F29: Completed | G29: Brand Dashboard | H29: — | I29: Rebate Campaigns | J29: Compare a card with its detail page. | M29: #4, #7
B30: 22 | C30: Create Rebate Campaign | D30: ① Basics: internal name, start/end, campaign image | E30: As specified. | F30: Completed | G30: Brand Dashboard | H30: — | I30: Rebate → Create | J30: Create a draft. | M30: #5
B31: 23 | C31: Create Rebate Campaign | D31: ② Eligible products (search, select, same-category check) | E31: Product search and selection. | F31: Completed | G31: Brand Dashboard | H31: — | I31: Rebate → Create | J31: Select 3 products. | M31: #5
B32: 24 | C32: Create Rebate Campaign | D32: ③ Offer setup: Free / BOGO Free / Buy 1 Get 1 50% / Buy X Get $Y | E32: All four with locked reward math. | F32: Completed | G32: Brand Dashboard + Backend / API | H32: — | I32: Rebate → Create | J32: Create one of each. | M32: #5
B33: 25 | C33: Create Rebate Campaign | D33: ④ Offer details & shopper wording (suggested, editable, 100/250 limits) + locked system rules | E33: Suggested wording + locked rules summary. | F33: Completed | G33: Brand Dashboard | H33: — | I33: Rebate → Create | J33: Edit the headline. | M33: #5
B34: 26 | C34: Create Rebate Campaign | D34: ⑤ Retailer availability, Request/Add Retailer, up to 3 Featured | E34: Directory, add retailer, featured. | F34: Completed | G34: Brand Dashboard | H34: — | I34: Rebate → Create | J34: Add a retailer; pick featured. | M34: #10
B35: 27 | C35: Create Rebate Campaign | D35: ⑥ Receipt eligibility: Any Retailer / Retailer Required | E35: Enforced on receipts; saved on claim. | F35: Completed | G35: Brand Dashboard + Backend / API | H35: — | I35: Rebate → Create | J35: Set Retailer Required; upload another store's receipt. | M35: #10
... B38: 30 | C38: Create Rebate Campaign | D38: Discovery geography (Nationwide / States / ZIP + radius) | E38: All three, multiple areas. | F38: Completed | G38: Brand Dashboard + Backend / API | H38: — | I38: Rebate → Create | J38: Set ZIP radius; test from outside it. | M38: #13
B39: 31 | C39: Create Rebate Campaign | D39: Meta Pixel tracking on/off (validated Pixel ID only) | E39: Per-campaign switch; Pixel from Settings. | F39: Completed | G39: Brand Dashboard + Shopper Website | H39: — | I39: Campaign page | J39: Turn tracking on. | K39: Pixel validation is a format check. | M39: #11
B40: 32 | C40: Create Rebate Campaign | D40: Live shopper preview (same data as published offer) | E40: Live preview in builder. | F40: Completed | G40: Brand Dashboard | H40: — | I40: Rebate → Create | J40: Edit and watch the preview. | M40: #5
B41: 33 | C41: Create Rebate Campaign | D41: Save Draft / Submit for Nibbl Review; revisions keep approved version live | E41: Full approval workflow. | F41: Completed | G41: Brand Dashboard + Admin Dashboard | H41: — | I41: Campaign page; Admin → Approvals | J41: Submit, request changes, approve. | M41: #7, #44
B42: 34 | C42: Create Rebate Campaign | D42: Existing reservation rule snapshot | E42: Each claim keeps its terms. | F42: Completed | G42: Backend / API | H42: — | I42: Backend | J42: Edit a live campaign; old claim unchanged. | M42: #8
B43: 35 | C43: Offer Type Inputs & Shopper Output | D43: Reward math per offer type, net eligible price, rounding; shopper output sources | E43: As specified. | F43: Completed | G43: Backend / API + Shopper Website | H43: — | I43: Website → offer page | J43: Compare offer page with campaign. | M43: #5
B44: 36 | C44: Campaign Detail Page | D44: ① Status · ② Summary + Preview Offer · ④ Performance · ⑤ Current cycle · ⑥ Review activity · ⑦ Actions | E44: All sections. | F44: Completed | G44: Brand Dashboard | H44: — | I44: Rebate → View Details | J44: Open a campaign. | M44: #7
...

Sheet Summary by Section
B2: Progress by Master Document Section
B4: Master Document Section | C4: Total | D4: Completed | E4: In Progress | F4: In Review | G4: Planned | H4: Completion
B5: Brand Dashboard Home | C5: =COUNTIF('Master Requirements Tracker'!$C$9:$C$158,B5) -> 8 | D5: =COUNTIFS('Master Requirements Tracker'!$C$9:$C$158,B5,'Master Requirements Tracker'!$F$9:$F$158,"Completed") -> 8 | E5: =COUNTIFS('Master Requirements Tracker'!$C$9:$C$158,B5,'Master Requirements Tracker'!$F$9:$F$158,"In Progress") -> 0 | F5: =COUNTIFS('Master Requirements Tracker'!$C$9:$C$158,B5,'Master Requirements Tracker'!$F$9:$F$158,"In Review") -> 0 | G5: =COUNTIFS('Master Requirements Tracker'!$C$9:$C$158,B5,'Master Requirements Tracker'!$F$9:$F$158,"Planned") -> 0 | H5: =IF(C5>0,D5/C5,0) -> 1
B6: Product Library | C6: =COUNTIF('Master Requirements Tracker'!$C$9:$C$158,B6) -> 10 | D6: =COUNTIFS('Master Requirements Tracker'!$C$9:$C$158,B6,'Master Requirements Tracker'!$F$9:$F$158,"Completed") -> 6 | E6: =COUNTIFS('Master Requirements Tracker'!$C$9:$C$158,B6,'Master Requirements Tracker'!$F$9:$F$158,"In Progress") -> 3 | F6: =COUNTIFS('Master Requirements Tracker'!$C$9:$C$158,B6,'Master Requirements Tracker'!$F$9:$F$158,"In Review") -> 0 | G6: =COUNTIFS('Master Requirements Tracker'!$C$9:$C$158,B6,'Master Requirements Tracker'!$F$9:$F$158,"Planned") -> 1 | H6: =IF(C6>0,D6/C6,0) -> 0.6
B7: Rebate Campaigns List | C7: =COUNTIF('Master Requirements Tracker'!$C$9:$C$158,B7) -> 3 | D7: =COUNTIFS('Master Requirements Tracker'!$C$9:$C$158,B7,'Master Requirements Tracker'!$F$9:$F$158,"Completed") -> 3 | E7: =COUNTIFS('Master Requirements Tracker'!$C$9:$C$158,B7,'Master Requirements Tracker'!$F$9:$F$158,"In Progress") -> 0 | F7: =COUNTIFS('Master Requirements Tracker'!$C$9:$C$158,B7,'Master Requirements Tracker'!$F$9:$F$158,"In Review") -> 0 | G7: =COUNTIFS('Master Requirements Tracker'!$C$9:$C$158,B7,'Master Requirements Tracker'!$F$9:$F$158,"Planned") -> 0 | H7: =IF(C7>0,D7/C7,0) -> 1
B8: Create Rebate Campaign | C8: =COUNTIF('Master Requirements Tracker'!$C$9:$C$158,B8) -> 13 | D8: =COUNTIFS('Master Requirements Tracker'!$C$9:$C$158,B8,'Master Requirements Tracker'!$F$9:$F$158,"Completed") -> 13 | E8: =COUNTIFS('Master Requirements Tracker'!$C$9:$C$158,B8,'Master Requirements Tracker'!$F$9:$F$158,"In Progress") -> 0 | F8: =COUNTIFS('Master Requirements Tracker'!$C$9:$C$158,B8,'Master Requirements Tracker'!$F$9:$F$158,"In Review") -> 0 | G8: =COUNTIFS('Master Requirements Tracker'!$C$9:$C$158,B8,'Master Requirements Tracker'!$F$9:$F$158,"Planned") -> 0 | H8: =IF(C8>0,D8/C8,0) -> 1
B9: Offer Type Inputs & Shopper Output | C9: =COUNTIF('Master Requirements Tracker'!$C$9:$C$158,B9) -> 1 | D9: =COUNTIFS('Master Requirements Tracker'!$C$9:$C$158,B9,'Master Requirements Tracker'!$F$9:$F$158,"Completed") -> 1 | E9: =COUNTIFS('Master Requirements Tracker'!$C$9:$C$158,B9,'Master Requirements Tracker'!$F$9:$F$158,"In Progress") -> 0 | F9: =COUNTIFS('Master Requirements Tracker'!$C$9:$C$158,B9,'Master Requirements Tracker'!$F$9:$F$158,"In Review") -> 0 | G9: =COUNTIFS('Master Requirements Tracker'!$C$9:$C$158,B9,'Master Requirements Tracker'!$F$9:$F$158,"Planned") -> 0 | H9: =IF(C9>0,D9/C9,0) -> 1
B10: Campaign Detail Page | C10: =COUNTIF('Master Requirements Tracker'!$C$9:$C$158,B10) -> 2 | D10: =COUNTIFS('Master Requirements Tracker'!$C$9:$C$158,B10,'Master Requirements Tracker'!$F$9:$F$158,"Completed") -> 2 | E10: =COUNTIFS('Master Requirements Tracker'!$C$9:$C$158,B10,'Master Requirements Tracker'!$F$9:$F$158,"In Progress") -> 0 | F10: =COUNTIFS('Master Requirements Tracker'!$C$9:$C$158,B10,'Master Requirements Tracker'!$F$9:$F$158,"In Review") -> 0 | G10: =COUNTIFS('Master Requirements Tracker'!$C$9:$C$158,B10,'Master Requirements Tracker'!$F$9:$F$158,"Planned") -> 0 | H10: =IF(C10>0,D10/C10,0) -> 1
B11: Effect on Existing Reservations | C11: =COUNTIF('Master Requirements Tracker'!$C$9:$C$158,B11) -> 3 | D11: =COUNTIFS('Master Requirements Tracker'!$C$9:$C$158,B11,'Master Requirements Tracker'!$F$9:$F$158,"Completed") -> 3 | E11: =COUNTIFS('Master Requirements Tracker'!$C$9:$C$158,B11,'Master Requirements Tracker'!$F$9:$F$158,"In Progress") -> 0 | F11: =COUNTIFS('Master Requirements Tracker'!$C$9:$C$158,B11,'Master Requirements Tracker'!$F$9:$F$158,"In Review") -> 0 | G11: =COUNTIFS('Master Requirements Tracker'!$C$9:$C$158,B11,'Master Requirements Tracker'!$F$9:$F$158,"Planned") -> 0 | H11: =IF(C11>0,D11/C11,0) -> 1
B12: Discovery | C12: =COUNTIF('Master Requirements Tracker'!$C$9:$C$158,B12) -> 7 | D12: =COUNTIFS('Master Requirements Tracker'!$C$9:$C$158,B12,'Master Requirements Tracker'!$F$9:$F$158,"Completed") -> 6 | E12: =COUNTIFS('Master Requirements Tracker'!$C$9:$C$158,B12,'Master Requirements Tracker'!$F$9:$F$158,"In Progress") -> 1 | F12: =COUNTIFS('Master Requirements Tracker'!$C$9:$C$158,B12,'Master Requirements Tracker'!$F$9:$F$158,"In Review") -> 0 | G12: =COUNTIFS('Master Requirements Tracker'!$C$9:$C$158,B12,'Master Requirements Tracker'!$F$9:$F$158,"Planned") -> 0 | H12: =IF(C12>0,D12/C12,0) -> 0.85714286
B13: Shopper Rebate Flow | C13: =COUNTIF('Master Requirements Tracker'!$C$9:$C$158,B13) -> 7 | D13: =COUNTIFS('Master Requirements Tracker'!$C$9:$C$158,B13,'Master Requirements Tracker'!$F$9:$F$158,"Completed") -> 5 | E13: =COUNTIFS('Master Requirements Tracker'!$C$9:$C$158,B13,'Master Requirements Tracker'!$F$9:$F$158,"In Progress") -> 2 | F13: =COUNTIFS('Master Requirements Tracker'!$C$9:$C$158,B13,'Master Requirements Tracker'!$F$9:$F$158,"In Review") -> 0 | G13: =COUNTIFS('Master Requirements Tracker'!$C$9:$C$158,B13,'Master Requirements Tracker'!$F$9:$F$158,"Planned") -> 0 | H13: =IF(C13>0,D13/C13,0) -> 0.71428571
B14: Receipt Submission | C14: =COUNTIF('Master Requirements Tracker'!$C$9:$C$158,B14) -> 1 | D14: =COUNTIFS('Master Requirements Tracker'!$C$9:$C$158,B14,'Master Requirements Tracker'!$F$9:$F$158,"Completed") -> 1 | E14: =COUNTIFS('Master Requirements Tracker'!$C$9:$C$158,B14,'Master Requirements Tracker'!$F$9:$F$158,"In Progress") -> 0 | F14: =COUNTIFS('Master Requirements Tracker'!$C$9:$C$158,B14,'Master Requirements Tracker'!$F$9:$F$158,"In Review") -> 0 | G14: =COUNTIFS('Master Requirements Tracker'!$C$9:$C$158,B14,'Master Requirements Tracker'!$F$9:$F$158,"Planned") -> 0 | H14: =IF(C14>0,D14/C14,0) -> 1
B15: Receipt Validation & Routing | C15: =COUNTIF('Master Requirements Tracker'!$C$9:$C$158,B15) -> 2 | D15: =COUNTIFS('Master Requirements Tracker'!$C$9:$C$158,B15,'Master Requirements Tracker'!$F$9:$F$158,"Completed") -> 2 | E15: =COUNTIFS('Master Requirements Tracker'!$C$9:$C$158,B15,'Master Requirements Tracker'!$F$9:$F$158,"In Progress") -> 0 | F15: =COUNTIFS('Master Requirements Tracker'!$C$9:$C$158,B15,'Master Requirements Tracker'!$F$9:$F$158,"In Review") -> 0 | G15: =COUNTIFS('Master Requirements Tracker'!$C$9:$C$158,B15,'Master Requirements Tracker'!$F$9:$F$158,"Planned") -> 0 | H15: =IF(C15>0,D15/C15,0) -> 1
B16: Receipt Outcomes | C16: =COUNTIF('Master Requirements Tracker'!$C$9:$C$158,B16) -> 2 | D16: =COUNTIFS('Master Requirements Tracker'!$C$9:$C$158,B16,'Master Requirements Tracker'!$F$9:$F$158,"Completed") -> 2 | E16: =COUNTIFS('Master Requirements Tracker'!$C$9:$C$158,B16,'Master Requirements Tracker'!$F$9:$F$158,"In Progress") -> 0 | F16: =COUNTIFS('Master Requirements Tracker'!$C$9:$C$158,B16,'Master Requirements Tracker'!$F$9:$F$158,"In Review") -> 0 | G16: =COUNTIFS('Master Requirements Tracker'!$C$9:$C$158,B16,'Master Requirements Tracker'!$F$9:$F$158,"Planned") -> 0 | H16: =IF(C16>0,D16/C16,0) -> 1
... B49: Cross-cutting | C49: =COUNTIF('Master Requirements Tracker'!$C$9:$C$158,B49) -> 3 | D49: =COUNTIFS('Master Requirements Tracker'!$C$9:$C$158,B49,'Master Requirements Tracker'!$F$9:$F$158,"Completed") -> 3 | E49: =COUNTIFS('Master Requirements Tracker'!$C$9:$C$158,B49,'Master Requirements Tracker'!$F$9:$F$158,"In Progress") -> 0 | F49: =COUNTIFS('Master Requirements Tracker'!$C$9:$C$158,B49,'Master Requirements Tracker'!$F$9:$F$158,"In Review") -> 0 | G49: =COUNTIFS('Master Requirements Tracker'!$C$9:$C$158,B49,'Master Requirements Tracker'!$F$9:$F$158,"Planned") -> 0 | H49: =IF(C49>0,D49/C49,0) -> 1
B50: Total | C50: =SUM(C5:C49) -> 150 | D50: =SUM(D5:D49) -> 130 | E50: =SUM(E5:E49) -> 13 | F50: =SUM(F5:F49) -> 2 | G50: =SUM(G5:G49) -> 5 | H50: =IF(C50>0,D50/C50,0) -> 0.86666667

Sheet Open Dependencies
B2: Open Dependencies (outside the development team)
B4: Owner | C4: What's Needed | D4: Current State | E4: Status
B5: Our team — Stripe | C5: Switch production to the live Stripe keys the client sent; retest checkout, top-up and auto-refill | D5: Client moved Stripe to live production (live keys + webhook secret received) | E5: In Progress
B6: Our team — Twilio | C6: Retest SMS-verified withdrawals; lock verified phones (change via admin + history) | D6: Twilio SMS verified on production 12 Oct 2026 (code sent to a Bangladesh number, delivered, approved). Remaining: one real website withdrawal with the SMS step | E6: In Progress
B7: Client — DNS | C7: Cloudflare access for www / brand / admin so the web apps can go live | D7: Done — www / brand / admin.joinnibbl.com live with SSL on 11 Oct 2026 | E7: Completed
B8: AI service (Sakibur) | C8: Adaptive review questions + AI review summary endpoints | D8: docs/AI_REVIEW_ENDPOINTS_SPEC.md shared | E8: In Review
B9: Mobile app developer | C9: App screens for shopper flows; required consents; X-Device-Id; referral progress | D9: Consumer API handover doc updated | E9: In Progress
B10: Client — AWS SES | C10: System email from @joinnibbl.com + bounce/complaint handling | D10: Done — production email switched to SES on 11 Oct 2026 (per the client's 10 Oct credentials doc). Note: the Master says Klaviyo sends system emails — confirm SES is the long-term choice | E10: Completed
B11: Client — Firebase | C11: Push via Workload Identity Federation (EC2 role sent) | D11: Waiting on client setup | E11: Planned
B12: Client — Klaviyo / SMS decision | C12: Master Settings §3: 'Klaviyo will send Nibbl system emails and SMS messages' (Nibbl's internal Klaviyo account). Brand SMS toggles are stored but no SMS is sent yet | D12: Decision needed: Klaviyo access (private API key + SMS sender) as the Master says, or use the existing Twilio account for brand SMS | E12: In Review
B13: Client — FAQ content | C13: Brand homepage 'Questions?' strip (Master mockup ④ only): Pricing / Review campaigns / Account & billing / General FAQ | D13: No FAQ content in the Master — need questions/answers or a help-centre link; shown as labels until then | E13: In Review

Sheet How to Use
B2: How to Use This Tracker
B4: Rows | C4: One row per requirement, in the Master Document's order, including the requirements shown only in the Master's screenshots. The Master stays the final source of truth. 'Checklist Ref' links to our internal 51-item checklist.
B5: Completed | C5: The full requirement works as intended, has been tested end to end and can be demonstrated. If any required sub-feature is missing, the row stays In Progress.
B6: In Progress | C6: Partly built. 'Open Items / Notes' says exactly what is still missing.
B7: In Review | C7: Our part is ready; waiting on a third party (e.g. the AI service endpoint or the client's Firebase setup).
B8: Planned | C8: Not built yet.
B9: Where to See It | C9: Screen path in the app. Brand Dashboard = brand.joinnibbl.com, Admin = admin.joinnibbl.com, Shopper Website = www.joinnibbl.com once the web apps are deployed (waiting on DNS); until then they run as a testable build against the live API.
B10: How to Test | C10: Short steps to see the requirement working. Use test accounts. Production still runs Stripe in test mode (card 4242 4242 4242 4242) until we switch to the live keys — see Open Dependencies.
B11: Evidence | C11: Yellow cells — paste a screenshot or screen-recording link (e.g. Loom / Google Drive) for each row as it's demonstrated.
B12: Mobile App | C12: Shopper rows show 'API ready — app developer to build/confirm': the backend is done and documented; the app developer builds the screen in the mobile app. '—' means not an app screen.
B13: Status column | C13: Pick from the dropdown; the totals at the top and the 'Summary by Section' sheet update automatically.
